Workbook

Sheet Fuel Resources ล่าสุด
A1: id | B1: scope_id | C1: scope_category_id | D1: category_name | E1: category_name_en | F1: ref_code | G1: resource | H1: sub_category | I1: unit | J1: ef_value | K1: value1_label | L1: value1_unit | M1: value2_label | N1: value2_unit | O1: ref_info | P1: ref_co2 | Q1: ref_fossil_ch4 | R1: ref_ch4 | S1: ref_n2o | T1: ref_sf6 | U1: ref_nf3 | V1: ref_hfcs | W1: ref_pfcs | X1: gwp100_hfcs | Y1: gwp100_pfcs | Z1: extraghg_ef | AA1: extraghg_gwp100 | AB1: ref_source | AC1: version | AD1: description | AE1: created_at | AF1: updated_at
A2: a0ee57a2-125e-563e-80eb-b94c84a9b957 | B2: 1 | C2: a1000001-0001-4001-8001-000000000001 | D2: 1) การเผาไหม้อยู่กับที่ (Stationary combustion) | E2: 1) Stationary combustion | F2: EF001-1 | G2: Natural Gas (NCV) | I2: SCF | J2: 0.05727759 | O2: IPCC defaults (2006), volume 2, chapter 2, table 2.3, p.2.18 - 2.19 และ Convert ค่าโดยอาศัยค่าคุณลักษณะเชื้อเพลิง | P2: 0.057222 | R2: 1.02e-06 | S2: 1.02e-07 | AB2: TGO | AC2: TGO 1 กรกฎาคม 2569 | AD2: IPCC defaults (2006), volume 2, chapter 2, table 2.3, p.2.18 - 2.19 และ Convert ค่าโดยอาศัยค่าคุณลักษณะเชื้อเพลิง | AE2: Mon Aug 03 2026 07:08:39 GMT+0700 (Indochina Time) | AF2: Tue Aug 25 2026 09:39:57 GMT+0700 (Indochina Time)
A3: dad8ac50-759e-5744-8abd-f25a5a86f839 | B3: 1 | C3: a1000001-0001-4001-8001-000000000001 | D3: 1) การเผาไหม้อยู่กับที่ (Stationary combustion) | E3: 1) Stationary combustion | F3: EF001-2 | G3: Natural Gas (NCV) | I3: MJ | J3: 0.0561545 | O3: IPCC defaults (2006), volume 2, chapter 2, table 2.3, p.2.18 - 2.19 และ Convert ค่าโดยอาศัยค่าคุณลักษณะเชื้อเพลิง | P3: 0.0561 | R3: 1e-06 | S3: 1e-07 | AB3: TGO | AC3: TGO 1 กรกฎาคม 2569 | AD3: IPCC defaults (2006), volume 2, chapter 2, table 2.3, p.2.18 - 2.19 และ Convert ค่าโดยอาศัยค่าคุณลักษณะเชื้อเพลิง | AE3: Mon Aug 03 2026 07:08:39 GMT+0700 (Indochina Time) | AF3: Tue Aug 25 2026 09:39:57 GMT+0700 (Indochina Time)
A4: f6ebbc11-77c6-53ba-97c9-1ad97c9e324b | B4: 1 | C4: a1000001-0001-4001-8001-000000000001 | D4: 1) การเผาไหม้อยู่กับที่ (Stationary combustion) | E4: 1) Stationary combustion | F4: EF001-3 | G4: Natural Gas (HHV) | I4: MJ | J4: 0.050151666 | O4: 2021 API Compendium, Table 4.3 &amp; Table 4.6 | P4: 0.0501 | R4: 9.48e-07 | S4: 9.48e-08 | AB4: TGO | AC4: TGO 1 กรกฎาคม 2569 | AD4: 2021 API Compendium, Table 4.3 &amp; Table 4.6 | AE4: Mon Aug 03 2026 07:08:39 GMT+0700 (Indochina Time) | AF4: Tue Aug 25 2026 09:39:57 GMT+0700 (Indochina Time)
A5: 50f61e85-bb23-50d3-ad42-5091e442310c | B5: 1 | C5: a1000001-0001-4001-8001-000000000001 | D5: 1) การเผาไหม้อยู่กับที่ (Stationary combustion) | E5: 1) Stationary combustion | F5: EF001-4 | G5: Natural Gas (HHV) | I5: MMBTU | J5: 52.9545 | O5: 2021 API Compendium, Table 4.3 &amp; Table 4.6 | P5: 52.9 | R5: 0.001 | S5: 0.0001 | AB5: TGO | AC5: TGO 1 กรกฎาคม 2569 | AD5: 2021 API Compendium, Table 4.3 &amp; Table 4.6 | AE5: Mon Aug 03 2026 07:08:39 GMT+0700 (Indochina Time) | AF5: Tue Aug 25 2026 09:39:57 GMT+0700 (Indochina Time)
A6: c375fbb3-503a-5b43-be3f-51b05c2a322f | B6: 1 | C6: a1000001-0001-4001-8001-000000000001 | D6: 1) การเผาไหม้อยู่กับที่ (Stationary combustion) | E6: 1) Stationary combustion | F6: EF001-5 | G6: LPG | I6: Liter | J6: 1.6811728 | O6: IPCC defaults (2006), volume 2, chapter 2, table 2.3, p.2.18 - 2.19 และ Convert ค่าโดยอาศัยค่าคุณลักษณะเชื้อเพลิง | P6: 1.679722 | R6: 2.662e-05 | S6: 2.662e-06 | AB6: TGO | AC6: TGO 1 กรกฎาคม 2569 | AD6: IPCC defaults (2006), volume 2, chapter 2, table 2.3, p.2.18 - 2.19 และ Convert ค่าโดยอาศัยค่าคุณลักษณะเชื้อเพลิง | AE6: Mon Aug 03 2026 07:08:39 GMT+0700 (Indochina Time) | AF6: Tue Aug 25 2026 09:39:57 GMT+0700 (Indochina Time)
A7: 487880ad-9005-5b05-91bb-c9691c0ff9a9 | B7: 1 | C7: a1000001-0001-4001-8001-000000000001 | D7: 1) การเผาไหม้อยู่กับที่ (Stationary combustion) | E7: 1) Stationary combustion | F7: EF001-6 | G7: LPG | I7: kg | J7: 3.1132829 | O7: IPCC defaults (2006), volume 2, chapter 2, table 2.3, p.2.18 - 2.19 และ Convert ค่าโดยอาศัยค่าคุณลักษณะเชื้อเพลิง | P7: 3.1105963 | R7: 4.9296296e-05 | S7: 4.9296296e-06 | AB7: TGO | AC7: TGO 1 กรกฎาคม 2569 | AD7: IPCC defaults (2006), volume 2, chapter 2, table 2.3, p.2.18 - 2.19 และ Convert ค่าโดยอาศัยค่าคุณลักษณะเชื้อเพลิง | AE7: Mon Aug 03 2026 07:08:39 GMT+0700 (Indochina Time) | AF7: Tue Aug 25 2026 09:39:57 GMT+0700 (Indochina Time)
A8: 7d8f2c1d-c653-588d-83a6-5a02f1b365db | B8: 1 | C8: a1000001-0001-4001-8001-000000000001 | D8: 1) การเผาไหม้อยู่กับที่ (Stationary combustion) | E8: 1) Stationary combustion | F8: EF001-7 | G8: Acetelyne | I8: kg | J8: 3.3846154 | O8: 2C2H2+502 &rarr; 4CO2+2H2O (MWC2H2 =26, MWCO2 =44) | P8: 3.3846154 | AB8: TGO | AC8: TGO 1 กรกฎาคม 2569 | AD8: 2C2H2+502 &rarr; 4CO2+2H2O (MWC2H2 =26, MWCO2 =44) | AE8: Mon Aug 03 2026 07:08:39 GMT+0700 (Indochina Time) | AF8: Tue Aug 25 2026 09:39:57 GMT+0700 (Indochina Time)
A9: a043a0bf-219f-51b6-96b3-a5dc51436ccf | B9: 1 | C9: a1000001-0001-4001-8001-000000000001 | D9: 1) การเผาไหม้อยู่กับที่ (Stationary combustion) | E9: 1) Stationary combustion | F9: EF001-8 | G9: Ethane | I9: kg | J9: 3.1428571 | O9: C2H4 + 3O2 --&gt; 2CO2 + 2H2O (MWC2H4 =28, MWCO2 =44) | P9: 3.1428571 | AB9: TGO | AC9: TGO 1 กรกฎาคม 2569 | AD9: C2H4 + 3O2 --&gt; 2CO2 + 2H2O (MWC2H4 =28, MWCO2 =44) | AE9: Mon Aug 03 2026 07:08:39 GMT+0700 (Indochina Time) | AF9: Tue Aug 25 2026 09:39:57 GMT+0700 (Indochina Time)
A10: b7c0a21b-893d-56aa-91f1-4fcff1659333 | B10: 1 | C10: a1000001-0001-4001-8001-000000000001 | D10: 1) การเผาไหม้อยู่กับที่ (Stationary combustion) | E10: 1) Stationary combustion | F10: EF001-9 | G10: Propane | I10: kg | J10: 3 | O10: C3H8+5O2&rarr;3CO2+4H2O (MWC3H8 =44, MWCO2 =44) | P10: 3 | AB10: TGO | AC10: TGO 1 กรกฎาคม 2569 | AD10: C3H8+5O2&rarr;3CO2+4H2O (MWC3H8 =44, MWCO2 =44) | AE10: Mon Aug 03 2026 07:08:39 GMT+0700 (Indochina Time) | AF10: Tue Aug 25 2026 09:39:57 GMT+0700 (Indochina Time)
A11: b1c485e5-dcc4-5df1-8bf1-42549f2d960a | B11: 1 | C11: a1000001-0001-4001-8001-000000000001 | D11: 1) การเผาไหม้อยู่กับที่ (Stationary combustion) | E11: 1) Stationary combustion | F11: EF001-10 | G11: Butane | I11: kg | J11: 3.0344828 | O11: 2C4H10+ 1302 &rarr; 8CO2+10H2O (MWC4H10 =58, MWCO2 =44) | P11: 3.0344828 | AB11: TGO | AC11: TGO 1 กรกฎาคม 2569 | AD11: 2C4H10+ 1302 &rarr; 8CO2+10H2O (MWC4H10 =58, MWCO2 =44) | AE11: Mon Aug 03 2026 07:08:39 GMT+0700 (Indochina Time) | AF11: Tue Aug 25 2026 09:39:57 GMT+0700 (Indochina Time)
A12: 53c5baf8-6655-5ce5-b0ad-f614fd9bcee9 | B12: 1 | C12: a1000001-0001-4001-8001-000000000001 | D12: 1) การเผาไหม้อยู่กับที่ (Stationary combustion) | E12: 1) Stationary combustion | F12: EF001-11 | G12: Fuel Oil A | I12: Liter | J12: 3.2197754 | O12: IPCC defaults (2006), volume 2, chapter 2, table 2.3, p.2.18 - 2.19 และ Convert ค่าโดยอาศัยค่าคุณลักษณะเชื้อเพลิง | P12: 3.2096984 | R12: 0.00012440692 | S12: 2.4881383e-05 | AB12: TGO | AC12: TGO 1 กรกฎาคม 2569 | AD12: IPCC defaults (2006), volume 2, chapter 2, table 2.3, p.2.18 - 2.19 และ Convert ค่าโดยอาศัยค่าคุณลักษณะเชื้อเพลิง | AE12: Mon Aug 03 2026 07:08:39 GMT+0700 (Indochina Time) | AF12: Tue Aug 25 2026 09:39:57 GMT+0700 (Indochina Time)
A13: 4fff6bdd-8300-55ec-8b51-1044a03833b0 | B13: 1 | C13: a1000001-0001-4001-8001-000000000001 | D13: 1) การเผาไหม้อยู่กับที่ (Stationary combustion) | E13: 1) Stationary combustion | F13: EF001-12 | G13: Fuel Oil C | I13: Liter | J13: 3.2454976 | O13: IPCC defaults (2006), volume 2, chapter 2, table 2.3, p.2.18 - 2.19 และ Convert ค่าโดยอาศัยค่าคุณลักษณะเชื้อเพลิง | P13: 3.2353401 | R13: 0.00012540078 | S13: 2.5080156e-05 | AB13: TGO | AC13: TGO 1 กรกฎาคม 2569 | AD13: IPCC defaults (2006), volume 2, chapter 2, table 2.3, p.2.18 - 2.19 และ Convert ค่าโดยอาศัยค่าคุณลักษณะเชื้อเพลิง | AE13: Mon Aug 03 2026 07:08:39 GMT+0700 (Indochina Time) | AF13: Tue Aug 25 2026 09:39:57 GMT+0700 (Indochina Time)
A14: b77bc1f8-5a08-5ca0-86f5-28018ca1f2ba | B14: 1 | C14: a1000001-0001-4001-8001-000000000001 | D14: 1) การเผาไหม้อยู่กับที่ (Stationary combustion) | E14: 1) Stationary combustion | F14: EF001-13 | G14: Jet Kerosene | I14: Liter | J14: 2.4772858 | O14: IPCC defaults (2006), volume 2, chapter 2, table 2.3, p.2.18 - 2.19 และ Convert ค่าโดยอาศัยค่าคุณลักษณะเชื้อเพลิง | P14: 2.468895 | R14: 0.00010359 | S14: 2.0718e-05 | AB14: TGO | AC14: TGO 1 กรกฎาคม 2569 | AD14: IPCC defaults (2006), volume 2, chapter 2, table 2.3, p.2.18 - 2.19 และ Convert ค่าโดยอาศัยค่าคุณลักษณะเชื้อเพลิง | AE14: Mon Aug 03 2026 07:08:39 GMT+0700 (Indochina Time) | AF14: Tue Aug 25 2026 09:39:57 GMT+0700 (Indochina Time)
A15: 93f612ea-5f5e-5c82-b387-bd6d8a34de32 | B15: 1 | C15: a1000001-0001-4001-8001-000000000001 | D15: 1) การเผาไหม้อยู่กับที่ (Stationary combustion) | E15: 1) Stationary combustion | F15: EF001-14 | G15: Other Kerosene | I15: Liter | J15: 2.4910978 | O15: IPCC defaults (2006), volume 2, chapter 2, table 2.3, p.2.18 - 2.19 และ Convert ค่าโดยอาศัยค่าคุณลักษณะเชื้อเพลิง | P15: 2.482707 | R15: 0.00010359 | S15: 2.0718e-05 | AB15: TGO | AC15: TGO 1 กรกฎาคม 2569 | AD15: IPCC defaults (2006), volume 2, chapter 2, table 2.3, p.2.18 - 2.19 และ Convert ค่าโดยอาศัยค่าคุณลักษณะเชื้อเพลิง | AE15: Mon Aug 03 2026 07:08:39 GMT+0700 (Indochina Time) | AF15: Tue Aug 25 2026 09:39:57 GMT+0700 (Indochina Time)
A16: 6a96f9f4-6414-5c55-9b62-8ff82d3a3a70 | B16: 1 | C16: a1000001-0001-4001-8001-000000000001 | D16: 1) การเผาไหม้อยู่กับที่ (Stationary combustion) | E16: 1) Stationary combustion | F16: EF001-15 | G16: Diesel | I16: Liter | J16: 2.7075721 | O16: IPCC defaults (2006), volume 2, chapter 2, table 2.3, p.2.18 - 2.19 และ Convert ค่าโดยอาศัยค่าคุณลักษณะเชื้อเพลิง | P16: 2.698722 | R16: 0.00010926 | S16: 2.1852e-05 | AB16: TGO | AC16: TGO 1 กรกฎาคม 2569 | AD16: IPCC defaults (2006), volume 2, chapter 2, table 2.3, p.2.18 - 2.19 และ Convert ค่าโดยอาศัยค่าคุณลักษณะเชื้อเพลิง | AE16: Mon Aug 03 2026 07:08:39 GMT+0700 (Indochina Time) | AF16: Tue Aug 25 2026 09:39:57 GMT+0700 (Indochina Time)
A17: 61d61b92-1130-520e-a129-45116fc45b7d | B17: 1 | C17: a1000001-0001-4001-8001-000000000001 | D17: 1) การเผาไหม้อยู่กับที่ (Stationary combustion) | E17: 1) Stationary combustion | F17: EF001-16 | G17: Gasoline | I17: Liter | J17: 2.1892136 | O17: IPCC defaults (2006), volume 2, chapter 2, table 2.3, p.2.18 - 2.19 และ Convert ค่าโดยอาศัยค่าคุณลักษณะเชื้อเพลิง | P17: 2.181564 | R17: 9.444e-05 | S17: 1.8888e-05 | AB17: TGO | AC17: TGO 1 กรกฎาคม 2569 | AD17: IPCC defaults (2006), volume 2, chapter 2, table 2.3, p.2.18 - 2.19 และ Convert ค่าโดยอาศัยค่าคุณลักษณะเชื้อเพลิง | AE17: Mon Aug 03 2026 07:08:39 GMT+0700 (Indochina Time) | AF17: Tue Aug 25 2026 09:39:57 GMT+0700 (Indochina Time)
A18: db81ce81-d4e8-572d-9b1a-ab4529a45e6b | B18: 1 | C18: a1000001-0001-4001-8001-000000000001 | D18: 1) การเผาไหม้อยู่กับที่ (Stationary combustion) | E18: 1) Stationary combustion | F18: EF001-17 | G18: Biodiesel | I18: Liter | J18: 1.6496185 | O18: IPCC defaults (2006), volume 2, chapter 2, table 2.3, p.2.18 - 2.19 และ Convert ค่าโดยอาศัยค่าคุณลักษณะเชื้อเพลิง | P18: 1.643976 | R18: 6.966e-05 | S18: 1.3932e-05 | AB18: TGO | AC18: TGO 1 กรกฎาคม 2569 | AD18: IPCC defaults (2006), volume 2, chapter 2, table 2.3, p.2.18 - 2.19 และ Convert ค่าโดยอาศัยค่าคุณลักษณะเชื้อเพลิง | AE18: Mon Aug 03 2026 07:08:39 GMT+0700 (Indochina Time) | AF18: Tue Aug 25 2026 09:39:57 GMT+0700 (Indochina Time)
A19: 49fb9283-37d8-51c1-90be-e7e8b7517ae6 | B19: 1 | C19: a1000001-0001-4001-8001-000000000001 | D19: 1) การเผาไหม้อยู่กับที่ (Stationary combustion) | E19: 1) Stationary combustion | F19: EF001-18 | G19: Bio-gasollne (Ethanol) | I19: Liter | J19: 1.5019201 | O19: IPCC defaults (2006), volume 2, chapter 2, table 2.3, p.2.18 - 2.19 และ Convert ค่าโดยอาศัยค่าคุณลักษณะเชื้อเพลิง | P19: 1.4967828 | R19: 6.3423e-05 | S19: 1.26846e-05 | AB19: TGO | AC19: TGO 1 กรกฎาคม 2569 | AD19: IPCC defaults (2006), volume 2, chapter 2, table 2.3, p.2.18 - 2.19 และ Convert ค่าโดยอาศัยค่าคุณลักษณะเชื้อเพลิง | AE19: Mon Aug 03 2026 07:08:39 GMT+0700 (Indochina Time) | AF19: Tue Aug 25 2026 09:39:57 GMT+0700 (Indochina Time)
A20: 269da535-e952-5f0a-af60-e34f4f648f08 | B20: 1 | C20: a1000001-0001-4001-8001-000000000001 | D20: 1) การเผาไหม้อยู่กับที่ (Stationary combustion) | E20: 1) Stationary combustion | F20: EF001-19 | G20: Diesel B7 (แบบคิด EF ของ Biofuel ด้วย) | I20: Liter | J20: 2.6335153 | O20: คิดที่สัดส่วนไบโอดีเซล (7%) | P20: 2.6248898 | R20: 0.000106488 | S20: 2.12976e-05 | AB20: TGO | AC20: TGO 1 กรกฎาคม 2569 | AD20: คิดที่สัดส่วนไบโอดีเซล (7%) | AE20: Mon Aug 03 2026 07:08:39 GMT+0700 (Indochina Time) | AF20: Tue Aug 25 2026 09:39:57 GMT+0700 (Indochina Time)
A21: 749fea82-640a-54ca-b5c1-107246baba52 | B21: 1 | C21: a1000001-0001-4001-8001-000000000001 | D21: 1) การเผาไหม้อยู่กับที่ (Stationary combustion) | E21: 1) Stationary combustion | F21: EF001-20 | G21: Diesel B7: Report in Scope 1 | I21: Liter | J21: 2.518437 | O21: นับเฉพาะ CO2 จาก fossil fuel, CH4 และ N2O | P21: 2.5098115 | R21: 0.000106488 | S21: 2.12976e-05 | AB21: TGO | AC21: TGO 1 กรกฎาคม 2569 | AD21: นับเฉพาะ CO2 จาก fossil fuel, CH4 และ N2O | AE21: Mon Aug 03 2026 07:08:39 GMT+0700 (Indochina Time) | AF21: Tue Aug 25 2026 09:39:57 GMT+0700 (Indochina Time)
A22: 71b90a87-ba56-5853-9d25-d15864344bdb | B22: 4 | C22: a1000004-0004-4004-8004-000000000014 | D22: แยกรายงานการใช้พลังงาน | E22: Energy Usage Reporting | F22: EF001-21 | G22: Diesel B7: Report in Biogenic CO2 emissions | I22: Liter | J22: 0.11507832 | O22: นับเฉพาะ CO2 จาก biofuel | P22: 0.11507832 | AB22: TGO | AC22: TGO 1 กรกฎาคม 2569 | AD22: นับเฉพาะ CO2 จาก biofuel | AE22: Mon Aug 03 2026 07:08:39 GMT+0700 (Indochina Time) | AF22: Tue Aug 25 2026 09:39:57 GMT+0700 (Indochina Time)
A23: 553235aa-2d60-585d-a0ba-0170649ae4d0 | B23: 1 | C23: a1000001-0001-4001-8001-000000000001 | D23: 1) การเผาไหม้อยู่กับที่ (Stationary combustion) | E23: 1) Stationary combustion | F23: EF001-22 | G23: Diesel B20 (แบบคิด EF ของ Biofuel ด้วย) | I23: Liter | J23: 2.4959813 | O23: คิดที่สัดส่วนไบโอดีเซล (20%) | P23: 2.4877728 | R23: 0.00010134 | S23: 2.0268e-05 | AB23: TGO | AC23: TGO 1 กรกฎาคม 2569 | AD23: คิดที่สัดส่วนไบโอดีเซล (20%) | AE23: Mon Aug 03 2026 07:08:39 GMT+0700 (Indochina Time) | AF23: Tue Aug 25 2026 09:39:57 GMT+0700 (Indochina Time)
A24: cdb45120-2d6e-5425-996d-45a98ffd0ba6 | B24: 1 | C24: a1000001-0001-4001-8001-000000000001 | D24: 1) การเผาไหม้อยู่กับที่ (Stationary combustion) | E24: 1) Stationary combustion | F24: EF001-23 | G24: Diesel B20: Report in Scope 1 | I24: Liter | J24: 2.1671861 | O24: นับเฉพาะ CO2 จาก fossil fuel, CH4 และ N2O | P24: 2.1589776 | R24: 0.00010134 | S24: 2.0268e-05 | AB24: TGO | AC24: TGO 1 กรกฎาคม 2569 | AD24: นับเฉพาะ CO2 จาก fossil fuel, CH4 และ N2O | AE24: Mon Aug 03 2026 07:08:39 GMT+0700 (Indochina Time) | AF24: Tue Aug 25 2026 09:39:57 GMT+0700 (Indochina Time)
A25: 693807d7-6064-5d4e-b732-282ca3fd8ef0 | B25: 4 | C25: a1000004-0004-4004-8004-000000000014 | D25: แยกรายงานการใช้พลังงาน | E25: Energy Usage Reporting | F25: EF001-24 | G25: Diesel B20: Report in Biogenic CO2 emissions | I25: Liter | J25: 0.3287952 | O25: นับเฉพาะ CO2 จาก biofuel | P25: 0.3287952 | AB25: TGO | AC25: TGO 1 กรกฎาคม 2569 | AD25: นับเฉพาะ CO2 จาก biofuel | AE25: Mon Aug 03 2026 07:08:39 GMT+0700 (Indochina Time) | AF25: Tue Aug 25 2026 09:39:57 GMT+0700 (Indochina Time)
A26: 8204e152-16b2-560e-a8dd-e060ae4c6eb5 | B26: 1 | C26: a1000001-0001-4001-8001-000000000001 | D26: 1) การเผาไหม้อยู่กับที่ (Stationary combustion) | E26: 1) Stationary combustion | F26: EF001-25 | G26: Gasohol (E10) | I26: Liter | J26: 2.1204843 | O26: คิดที่สัดส่วนเอทานอล (10%) | P26: 2.1130859 | R26: 9.13383e-05 | S26: 1.826766e-05 | AB26: TGO | AC26: TGO 1 กรกฎาคม 2569 | AD26: คิดที่สัดส่วนเอทานอล (10%) | AE26: Mon Aug 03 2026 07:08:39 GMT+0700 (Indochina Time) | AF26: Tue Aug 25 2026 09:39:57 GMT+0700 (Indochina Time)
A27: 03312a7d-03c2-55d6-bd68-91057e71640f | B27: 1 | C27: a1000001-0001-4001-8001-000000000001 | D27: 1) การเผาไหม้อยู่กับที่ (Stationary combustion) | E27: 1) Stationary combustion | F27: EF001-26 | G27: Gasohol E10: Report in Scope 1 | I27: Liter | J27: 1.970806 | O27: นับเฉพาะ CO2 จาก fossil fuel, CH4 และ N2O | P27: 1.9634076 | R27: 9.13383e-05 | S27: 1.826766e-05 | AB27: TGO | AC27: TGO 1 กรกฎาคม 2569 | AD27: นับเฉพาะ CO2 จาก fossil fuel, CH4 และ N2O | AE27: Mon Aug 03 2026 07:08:39 GMT+0700 (Indochina Time) | AF27: Tue Aug 25 2026 09:39:57 GMT+0700 (Indochina Time)
A28: 6ea4c009-c610-563e-98f6-7eb9e96fc4b6 | B28: 4 | C28: a1000004-0004-4004-8004-000000000014 | D28: แยกรายงานการใช้พลังงาน | E28: Energy Usage Reporting | F28: EF001-27 | G28: Gasohol E10: Report in Biogenic CO2 emissions | I28: Liter | J28: 0.14967828 | O28: นับเฉพาะ CO2 จาก biofuel | P28: 0.14967828 | AB28: TGO | AC28: TGO 1 กรกฎาคม 2569 | AD28: นับเฉพาะ CO2 จาก biofuel | AE28: Mon Aug 03 2026 07:08:39 GMT+0700 (Indochina Time) | AF28: Tue Aug 25 2026 09:39:57 GMT+0700 (Indochina Time)
A29: 7389d746-0aaa-5860-9608-218054fc7e76 | B29: 1 | C29: a1000001-0001-4001-8001-000000000001 | D29: 1) การเผาไหม้อยู่กับที่ (Stationary combustion) | E29: 1) Stationary combustion | F29: EF001-28 | G29: Gasohol (E20) | I29: Liter | J29: 2.0517549 | O29: คิดที่สัดส่วนเอทานอล (20%) | P29: 2.0446078 | R29: 8.82366e-05 | S29: 1.764732e-05 | AB29: TGO | AC29: TGO 1 กรกฎาคม 2569 | AD29: คิดที่สัดส่วนเอทานอล (20%) | AE29: Mon Aug 03 2026 07:08:39 GMT+0700 (Indochina Time) | AF29: Tue Aug 25 2026 09:39:57 GMT+0700 (Indochina Time)
A30: 028ed101-a815-5f61-a5dd-d9e46481dfa4 | B30: 1 | C30: a1000001-0001-4001-8001-000000000001 | D30: 1) การเผาไหม้อยู่กับที่ (Stationary combustion) | E30: 1) Stationary combustion | F30: EF001-29 | G30: Gasohol E20: Report in Scope 1 | I30: Liter | J30: 1.7523984 | O30: นับเฉพาะ CO2 จาก fossil fuel, CH4 และ N2O | P30: 1.7452512 | R30: 8.82366e-05 | S30: 1.764732e-05 | AB30: TGO | AC30: TGO 1 กรกฎาคม 2569 | AD30: นับเฉพาะ CO2 จาก fossil fuel, CH4 และ N2O | AE30: Mon Aug 03 2026 07:08:39 GMT+0700 (Indochina Time) | AF30: Tue Aug 25 2026 09:39:57 GMT+0700 (Indochina Time)
A31: 9085cfff-065e-57af-b075-2a192f8d3e16 | B31: 4 | C31: a1000004-0004-4004-8004-000000000014 | D31: แยกรายงานการใช้พลังงาน | E31: Energy Usage Reporting | F31: EF001-30 | G31: Gasohol E20: Report in Biogenic CO2 emissions | I31: Liter | J31: 0.29935656 | O31: นับเฉพาะ CO2 จาก biofuel | P31: 0.29935656 | AB31: TGO | AC31: TGO 1 กรกฎาคม 2569 | AD31: นับเฉพาะ CO2 จาก biofuel | AE31: Mon Aug 03 2026 07:08:39 GMT+0700 (Indochina Time) | AF31: Tue Aug 25 2026 09:39:57 GMT+0700 (Indochina Time)
A32: 9801ca62-9692-5003-9123-1a697d0058d0 | B32: 1 | C32: a1000001-0001-4001-8001-000000000001 | D32: 1) การเผาไหม้อยู่กับที่ (Stationary combustion) | E32: 1) Stationary combustion | F32: EF001-31 | G32: Gasohol (E85) | I32: Liter | J32: 1.6050141 | O32: คิดที่สัดส่วนเอทานอล (85%) | P32: 1.5995 | R32: 6.807555e-05 | S32: 1.361511e-05 | AB32: TGO | AC32: TGO 1 กรกฎาคม 2569 | AD32: คิดที่สัดส่วนเอทานอล (85%) | AE32: Mon Aug 03 2026 07:08:39 GMT+0700 (Indochina Time) | AF32: Tue Aug 25 2026 09:39:57 GMT+0700 (Indochina Time)
A33: 5d371e99-8abf-5022-8e2d-b415db881b80 | B33: 1 | C33: a1000001-0001-4001-8001-000000000001 | D33: 1) การเผาไหม้อยู่กับที่ (Stationary combustion) | E33: 1) Stationary combustion | F33: EF001-32 | G33: Gasohol E85: Report in Scope 1 | I33: Liter | J33: 0.33274872 | O33: นับเฉพาะ CO2 จาก fossil fuel, CH4 และ N2O | P33: 0.3272346 | R33: 6.807555e-05 | S33: 1.361511e-05 | AB33: TGO | AC33: TGO 1 กรกฎาคม 2569 | AD33: นับเฉพาะ CO2 จาก fossil fuel, CH4 และ N2O | AE33: Mon Aug 03 2026 07:08:39 GMT+0700 (Indochina Time) | AF33: Tue Aug 25 2026 09:39:57 GMT+0700 (Indochina Time)
A34: 9ec31e93-884d-5ee6-a053-b041a2622c27 | B34: 4 | C34: a1000004-0004-4004-8004-000000000014 | D34: แยกรายงานการใช้พลังงาน | E34: Energy Usage Reporting | F34: EF001-33 | G34: Gasohol E85: Report in Biogenic CO2 emissions | I34: Liter | J34: 1.2722654 | O34: นับเฉพาะ CO2 จาก biofuel | P34: 1.2722654 | AB34: TGO | AC34: TGO 1 กรกฎาคม 2569 | AD34: นับเฉพาะ CO2 จาก biofuel | AE34: Mon Aug 03 2026 07:08:39 GMT+0700 (Indochina Time) | AF34: Tue Aug 25 2026 09:39:57 GMT+0700 (Indochina Time)
A35: c0355b81-fa8e-5c6c-8e00-e7c7ba5f0fdc | B35: 1 | C35: a1000001-0001-4001-8001-000000000001 | D35: 1) การเผาไหม้อยู่กับที่ (Stationary combustion) | E35: 1) Stationary combustion | F35: EF001-34 | G35: Lignite | I35: kg | J35: 1.2099623 | O35: IPCC defaults (2006), volume 2, chapter 2, table 2.3, p.2.18 - 2.19 และ Convert ค่าโดยอาศัยค่าคุณลักษณะเชื้อเพลิง | P35: 1.2019 | R35: 0.000119 | S35: 1.785e-05 | AB35: TGO | AC35: TGO 1 กรกฎาคม 2569 | AD35: IPCC defaults (2006), volume 2, chapter 2, table 2.3, p.2.18 - 2.19 และ Convert ค่าโดยอาศัยค่าคุณลักษณะเชื้อเพลิง | AE35: Mon Aug 03 2026 07:08:39 GMT+0700 (Indochina Time) | AF35: Tue Aug 25 2026 09:39:57 GMT+0700 (Indochina Time)
A36: 2acabfa9-674d-5aa9-b824-86b6de3e6070 | B36: 1 | C36: a1000001-0001-4001-8001-000000000001 | D36: 1) การเผาไหม้อยู่กับที่ (Stationary combustion) | E36: 1) Stationary combustion | F36: EF001-35 | G36: Anthracite | I36: kg | J36: 3.1078935 | O36: IPCC defaults (2006), volume 2, chapter 2, table 2.3, p.2.18 - 2.19 และ Convert ค่าโดยอาศัยค่าคุณลักษณะเชื้อเพลิง | P36: 3.08662 | R36: 0.000314 | S36: 4.71e-05 | AB36: TGO | AC36: TGO 1 กรกฎาคม 2569 | AD36: IPCC defaults (2006), volume 2, chapter 2, table 2.3, p.2.18 - 2.19 และ Convert ค่าโดยอาศัยค่าคุณลักษณะเชื้อเพลิง | AE36: Mon Aug 03 2026 07:08:39 GMT+0700 (Indochina Time) | AF36: Tue Aug 25 2026 09:39:57 GMT+0700 (Indochina Time)
A37: 57767ef0-d8e2-50e4-8e81-3e8a86187244 | B37: 1 | C37: a1000001-0001-4001-8001-000000000001 | D37: 1) การเผาไหม้อยู่กับที่ (Stationary combustion) | E37: 1) Stationary combustion | F37: EF001-36 | G37: Bituminous Coal | I37: kg | J37: 2.5124677 | O37: IPCC defaults (2006), volume 2, chapter 2, table 2.3, p.2.18 - 2.19 และ Convert ค่าโดยอาศัยค่าคุณลักษณะเชื้อเพลิง | P37: 2.494602 | R37: 0.0002637 | S37: 3.9555e-05 | AB37: TGO | AC37: TGO 1 กรกฎาคม 2569 | AD37: IPCC defaults (2006), volume 2, chapter 2, table 2.3, p.2.18 - 2.19 และ Convert ค่าโดยอาศัยค่าคุณลักษณะเชื้อเพลิง | AE37: Mon Aug 03 2026 07:08:39 GMT+0700 (Indochina Time) | AF37: Tue Aug 25 2026 09:39:57 GMT+0700 (Indochina Time)
A38: 143c6a78-13b5-58a7-b131-aff800d2fee5 | B38: 1 | C38: a1000001-0001-4001-8001-000000000001 | D38: 1) การเผาไหม้อยู่กับที่ (Stationary combustion) | E38: 1) Stationary combustion | F38: EF001-37 | G38: Coking Coal | I38: kg | J38: 2.6325173 | O38: IPCC defaults (2006), volume 2, chapter 2, table 2.3, p.2.18 - 2.19 และ Convert ค่าโดยอาศัยค่าคุณลักษณะเชื้อเพลิง | P38: 2.613798 | R38: 0.0002763 | S38: 4.1445e-05 | AB38: TGO | AC38: TGO 1 กรกฎาคม 2569 | AD38: IPCC defaults (2006), volume 2, chapter 2, table 2.3, p.2.18 - 2.19 และ Convert ค่าโดยอาศัยค่าคุณลักษณะเชื้อเพลิง | AE38: Mon Aug 03 2026 07:08:39 GMT+0700 (Indochina Time) | AF38: Tue Aug 25 2026 09:39:57 GMT+0700 (Indochina Time)
A39: 139250fc-17f7-500e-a55f-08208350b65c | B39: 1 | C39: a1000001-0001-4001-8001-000000000001 | D39: 1) การเผาไหม้อยู่กับที่ (Stationary combustion) | E39: 1) Stationary combustion | F39: EF001-38 | G39: Fuel wood | I39: kg | J39: 1.821261 | O39: IPCC defaults (2006), volume 2, chapter 2, table 2.3, p.2.18 - 2.19 และ Convert ค่าโดยอาศัยค่าคุณลักษณะเชื้อเพลิง | P39: 1.79088 | R39: 0.0004797 | S39: 6.396e-05 | AB39: TGO | AC39: TGO 1 กรกฎาคม 2569 | AD39: IPCC defaults (2006), volume 2, chapter 2, table 2.3, p.2.18 - 2.19 และ Convert ค่าโดยอาศัยค่าคุณลักษณะเชื้อเพลิง | AE39: Mon Aug 03 2026 07:08:39 GMT+0700 (Indochina Time) | AF39: Tue Aug 25 2026 09:39:57 GMT+0700 (Indochina Time)
A40: c0caace4-f789-5a17-9ba0-63138a6ff8fe | B40: 1 | C40: a1000001-0001-4001-8001-000000000001 | D40: 1) การเผาไหม้อยู่กับที่ (Stationary combustion) | E40: 1) Stationary combustion | F40: EF001-39 | G40: Fuel wood: Report in Scope 1 | I40: kg | J40: 0.030381 | O40: นับเฉพาะ CH4 และ N2O | R40: 0.0004797 | S40: 6.396e-05 | AB40: TGO | AC40: TGO 1 กรกฎาคม 2569 | AD40: นับเฉพาะ CH4 และ N2O | AE40: Mon Aug 03 2026 07:08:39 GMT+0700 (Indochina Time) | AF40: Tue Aug 25 2026 09:39:57 GMT+0700 (Indochina Time)
...

Sheet fuel_resources ที่ต้องเพิ่ม
A1: id | B1: scope_category_id | C1: resource | D1: sub_category | E1: unit | F1: ef_value | J1: value1_label | L1: value1_unit | M1: value2_label | N1: value2_unit | O1: ref_info | P1: ref_co2 | Q1: ref_fossil_ch4 | R1: ref_ch4 | S1: ref_n2o | T1: ref_sf6 | U1: ref_nf3 | V1: ref_hfcs | W1: ref_pfcs | X1: gwp100_hfcs | Y1: gwp100_pfcs | Z1: extraghg_ef | AA1: extraghg_gwp100 | AB1: ref_source | AC1: version | AD1: ref_code | AE1: sort_index | AF1: multiplier | AG1: description | AH1: meta
A2: ee0888d1-b4b9-5c44-83df-d0a7ab889acd | B2: a1000001-0001-4001-8001-000000000001 | C2: Acetelyne: kg | E2: kg | F2: 3.3846154 | G2: ='Fuel Resources ล่าสุด'!G2 -> Natural Gas (NCV) | H2: =IF(COUNTIF(G:G,C2)>0,"ซ้ำกัน","ไม่ซ้ำกัน") -> ไม่ซ้ำกัน | I2: {=_xlfn._xlws.FILTER(C2:C1798,COUNTIF(G2:G1798,C2:C1798)=0)} -> Acetelyne: kg | O2: 2C2H2+502 → 4CO2+2H2O (MWC2H2 =26, MWCO2 =44) | P2: 3.3846154 | Q2: 0 | R2: 0 | S2: 0 | AC2: พฤษภาคม 2569 | AF2: 1 | AH2: {}
A3: cf958594-d2b3-5115-aed7-30896180ea46 | B3: a1000003-0003-4003-8003-000000000007 | C3: Acrylonitrile Butadiene Styrene (ABS) | D3: กลุ่มปิโตรเคมี | E3: kg | F3: 4.1597 | G3: ='Fuel Resources ล่าสุด'!G3 -> Natural Gas (NCV) | H3: =IF(COUNTIF(G:G,C3)>0,"ซ้ำกัน","ไม่ซ้ำกัน") -> ซ้ำกัน | I3: Antracite: kg | O3: Thai National LCI Database, TIIS-MTEC-NSTDA (with TGO electricity 2016-2018) | AC3: พฤษภาคม 2569 | AF3: 1 | AH3: {}
A4: e219b9cc-f1a6-5de5-815f-a00ddddf58f7 | B4: a1000003-0003-4003-8003-000000000007 | C4: Acrylonitrile Butadiene Styrene (ABS) | D4: กลุ่มปิโตรเคมี | E4: kg | F4: 4.5845 | G4: ='Fuel Resources ล่าสุด'!G4 -> Natural Gas (HHV) | H4: =IF(COUNTIF(G:G,C4)>0,"ซ้ำกัน","ไม่ซ้ำกัน") -> ซ้ำกัน | I4: Biodiesel: L | O4: TGO_CFP_Thai National LCI Database, TIIS-MTEC-NSTDA (with TGO electricity 2022-2024) | AC4: พฤษภาคม 2569 | AF4: 1 | AH4: {}
A5: dd40f44e-e037-5b57-a66f-29975ad67984 | B5: a1000001-0001-4001-8001-000000000005 | C5: Aerobic treatment plant Not well managed | E5: kgCO2 | F5: 2.1 | G5: ='Fuel Resources ล่าสุด'!G5 -> Natural Gas (HHV) | H5: =IF(COUNTIF(G:G,C5)>0,"ซ้ำกัน","ไม่ซ้ำกัน") -> ซ้ำกัน | I5: Biodiesel: L | J5: ปริมาณน้ำเสีย | L5: m3 | M5: ปริมาน COD ที่ออกจากระบบ | N5: kg/m3 | O5: IPCC Vol.5 table 6.8 | R5: 1 | AC5: พฤษภาคม 2569 | AF5: 1 | AH5: {}
A6: 3fdffa80-203a-5609-8776-9fd9902f7a99 | B6: a1000001-0001-4001-8001-000000000005 | C6: Aerobic treatment plant well managed | E6: kgCO2 | F6: 0 | G6: ='Fuel Resources ล่าสุด'!G6 -> LPG | H6: =IF(COUNTIF(G:G,C6)>0,"ซ้ำกัน","ไม่ซ้ำกัน") -> ซ้ำกัน | I6: Biodiesel: L | J6: ปริมาณน้ำเสีย | L6: m3 | M6: ปริมาน COD ที่ออกจากระบบ | N6: kg/m3 | O6: IPCC Vol.5 table 6.8 | R6: 1 | AC6: พฤษภาคม 2569 | AF6: 1 | AH6: {}
A7: 13a345b6-7b7e-57da-bc79-1238c7c1eadf | B7: a1000001-0001-4001-8001-000000000005 | C7: Anaerobic deep lagoon | E7: kgCO2 | F7: 5.6 | G7: ='Fuel Resources ล่าสุด'!G7 -> LPG | H7: =IF(COUNTIF(G:G,C7)>0,"ซ้ำกัน","ไม่ซ้ำกัน") -> ซ้ำกัน | I7: Biogasollne (Ethanol) | J7: ปริมาณน้ำเสีย | L7: m3 | M7: ปริมาน COD ที่ออกจากระบบ | N7: kg/m3 | O7: IPCC Vol.5 table 6.8 | R7: 1 | AC7: พฤษภาคม 2569 | AF7: 1 | AH7: {}
A8: e2eeec62-a329-5244-9416-b84accbf99fe | B8: a1000001-0001-4001-8001-000000000005 | C8: Anaerobic digester for sludge | E8: kgCO2 | F8: 5.6 | G8: ='Fuel Resources ล่าสุด'!G8 -> Acetelyne | H8: =IF(COUNTIF(G:G,C8)>0,"ซ้ำกัน","ไม่ซ้ำกัน") -> ซ้ำกัน | I8: Bituminous Coal: kg | J8: ปริมาณน้ำเสีย | L8: m3 | M8: ปริมาน COD ที่ออกจากระบบ | N8: kg/m3 | O8: IPCC Vol.5 table 6.8 | R8: 1 | AC8: พฤษภาคม 2569 | AF8: 1 | AH8: {}
A9: 8b9f16cd-2513-5e2f-967a-53e52a6c583e | B9: a1000001-0001-4001-8001-000000000005 | C9: Anaerobic reactor | E9: kgCO2 | F9: 5.6 | G9: ='Fuel Resources ล่าสุด'!G9 -> Ethane | H9: =IF(COUNTIF(G:G,C9)>0,"ซ้ำกัน","ไม่ซ้ำกัน") -> ซ้ำกัน | I9: Butane: kg | J9: ปริมาณน้ำเสีย | L9: m3 | M9: ปริมาน COD ที่ออกจากระบบ | N9: kg/m3 | O9: IPCC Vol.5 table 6.8 | R9: 1 | AC9: พฤษภาคม 2569 | AF9: 1 | AH9: {}
A10: f46ba01f-f2c9-5df7-853a-49c4a3938ad2 | B10: a1000001-0001-4001-8001-000000000005 | C10: Anaerobic shallow lagoon | E10: kgCO2 | F10: 1.4 | G10: ='Fuel Resources ล่าสุด'!G10 -> Propane | H10: =IF(COUNTIF(G:G,C10)>0,"ซ้ำกัน","ไม่ซ้ำกัน") -> ซ้ำกัน | I10: Carbon dioxide (ก๊าซคาร์บอนไดออกไซด์) | J10: ปริมาณน้ำเสีย | L10: m3 | M10: ปริมาน COD ที่ออกจากระบบ | N10: kg/m3 | O10: IPCC Vol.5 table 6.8 | R10: 1 | AC10: พฤษภาคม 2569 | AF10: 1 | AH10: {}
A11: 327f9882-e40e-55b0-8223-e54f569d5a57 | B11: a1000001-0001-4001-8001-000000000001 | C11: Antracite: kg | E11: kg | F11: 3.1078935 | G11: ='Fuel Resources ล่าสุด'!G11 -> Butane | H11: =IF(COUNTIF(G:G,C11)>0,"ซ้ำกัน","ไม่ซ้ำกัน") -> ไม่ซ้ำกัน | I11: Carbon dioxide (ก๊าซคาร์บอนไดออกไซด์) | O11: IPCC defaults (2006), volume 2, chapter 2, table 2.3, p.2.18 - 2.19 และ Convert ค่าโดยอาศัยค่าคุณลักษณะเชื้อเพลิง | P11: 3.08662 | Q11: 0 | R11: 0.000314 | S11: 4.71e-05 | AC11: พฤษภาคม 2569 | AF11: 1 | AH11: {}
A12: b08891b3-fe46-5192-909c-60300690967d | B12: a1000004-0004-4004-8004-000000000014 | C12: Baggasse | E12: kg | F12: 0.753 | G12: ='Fuel Resources ล่าสุด'!G12 -> Fuel Oil A | H12: =IF(COUNTIF(G:G,C12)>0,"ซ้ำกัน","ไม่ซ้ำกัน") -> ซ้ำกัน | I12: Carbon dioxide (ก๊าซคาร์บอนไดออกไซด์) | O12: IPCC defaults (2006), volume 2, chapter 2, table 2.3, p.2.18 - 2.19 และ Convert ค่าโดยอาศัยค่าคุณลักษณะเชื้อเพลิง | AC12: พฤษภาคม 2569 | AF12: 1 | AH12: {}
A13: e7327bfc-1e5b-5235-9dea-610ab5cf0979 | B13: a1000001-0001-4001-8001-000000000001 | C13: Baggasse | E13: kg | F13: 0.014307 | G13: ='Fuel Resources ล่าสุด'!G13 -> Fuel Oil C | H13: =IF(COUNTIF(G:G,C13)>0,"ซ้ำกัน","ไม่ซ้ำกัน") -> ซ้ำกัน | I13: Chemical tanker | O13: IPCC defaults (2006), volume 2, chapter 2, table 2.3, p.2.18 - 2.19 และ Convert ค่าโดยอาศัยค่าคุณลักษณะเชื้อเพลิง | Q13: 0 | R13: 0.0002259 | S13: 3.012e-05 | AC13: พฤษภาคม 2569 | AF13: 1 | AH13: {}
A14: da67b128-d9f6-5124-9d9e-f260c3be146f | B14: a1000003-0003-4003-8003-000000000007 | C14: Benzene | D14: กลุ่มปิโตรเคมี | E14: kg | F14: 1.3268 | G14: ='Fuel Resources ล่าสุด'!G14 -> Jet Kerosene | H14: =IF(COUNTIF(G:G,C14)>0,"ซ้ำกัน","ไม่ซ้ำกัน") -> ซ้ำกัน | I14: Chemical tanker | O14: Thai National LCI Database, TIIS-MTEC-NSTDA (with TGO electricity 2016-2018) | AC14: พฤษภาคม 2569 | AF14: 1 | AH14: {}
A15: 965853d3-7431-541e-bb37-5e834f4aa3f2 | B15: a1000003-0003-4003-8003-000000000007 | C15: Benzene | D15: กลุ่มปิโตรเคมี | E15: kg | F15: 1.6128 | G15: ='Fuel Resources ล่าสุด'!G15 -> Other Kerosene | H15: =IF(COUNTIF(G:G,C15)>0,"ซ้ำกัน","ไม่ซ้ำกัน") -> ซ้ำกัน | I15: CNG: kg | O15: TGO_CFP_Thai National LCI Database, TIIS-MTEC-NSTDA (with TGO electricity 2022-2024) | AC15: พฤษภาคม 2569 | AF15: 1 | AH15: {}
A16: fb90a3b1-9bca-52c1-bbfd-cb72d9930e19 | B16: a1000001-0001-4001-8001-000000000001 | C16: Biodiesel: L | E16: Liter | F16: 1.6496185 | G16: ='Fuel Resources ล่าสุด'!G16 -> Diesel | H16: =IF(COUNTIF(G:G,C16)>0,"ซ้ำกัน","ไม่ซ้ำกัน") -> ไม่ซ้ำกัน | I16: Coking Coal: kg | O16: IPCC defaults (2006), volume 2, chapter 2, table 2.3, p.2.18 - 2.19 และ Convert ค่าโดยอาศัยค่าคุณลักษณะเชื้อเพลิง | P16: 1.643976 | R16: 6.966e-05 | S16: 1.3932e-05 | AC16: พฤษภาคม 2569 | AF16: 1 | AH16: {}
A17: b58a1e2f-bcb3-5f5b-99eb-a2e67bbc4a92 | B17: a1000001-0001-4001-8001-000000000002 | C17: Biodiesel: L | E17: Liter | F17: 1.643976 | G17: ='Fuel Resources ล่าสุด'!G17 -> Gasoline | H17: =IF(COUNTIF(G:G,C17)>0,"ซ้ำกัน","ไม่ซ้ำกัน") -> ไม่ซ้ำกัน | I17: Compressed Natural Gas | O17: IPCC defaults (2006) และ Convert ค่าโดยอาศัยค่าคุณลักษณะเชื้อเพลิง | P17: 1.643976 | AC17: พฤษภาคม 2569 | AF17: 1 | AH17: {}
A18: 4e0e4b29-8458-5d3a-bd54-e074919c865d | B18: a1000001-0001-4001-8001-000000000003 | C18: Biodiesel: L | E18: Liter | F18: 1.6705095 | G18: ='Fuel Resources ล่าสุด'!G18 -> Biodiesel | H18: =IF(COUNTIF(G:G,C18)>0,"ซ้ำกัน","ไม่ซ้ำกัน") -> ไม่ซ้ำกัน | I18: Compressed Natural Gas | O18: IPCC defaults (2006), volume 2, chapter 3, table 3.2.1 & 3.2.2 และ Convert ค่าโดยอาศัยค่าคุณลักษณะเชื้อเพลิง | P18: 1.643976 | Q18: 0 | R18: 9.0558e-05 | S18: 9.0558e-05 | AC18: พฤษภาคม 2569 | AF18: 1 | AH18: {}
A19: e6d4aef3-f57e-5eb6-ad47-12195f77bd29 | B19: a1000004-0004-4004-8004-000000000014 | C19: Biogas | E19: m3 | F19: 1.142778 | G19: ='Fuel Resources ล่าสุด'!G19 -> Bio-gasollne (Ethanol) | H19: =IF(COUNTIF(G:G,C19)>0,"ซ้ำกัน","ไม่ซ้ำกัน") -> ซ้ำกัน | I19: Compressed Natural Gas | O19: IPCC defaults (2006), volume 2, chapter 2, table 2.3, p.2.18 - 2.19 และ Convert ค่าโดยอาศัยค่าคุณลักษณะเชื้อเพลิง | AC19: พฤษภาคม 2569 | AF19: 1 | AH19: {}
A20: 359ba126-f70e-5a32-b975-9bc2950806b6 | B20: a1000001-0001-4001-8001-000000000001 | C20: Biogas | E20: m3 | F20: 0.001140685 | G20: ='Fuel Resources ล่าสุด'!G20 -> Diesel B7 (แบบคิด EF ของ Biofuel ด้วย) | H20: =IF(COUNTIF(G:G,C20)>0,"ซ้ำกัน","ไม่ซ้ำกัน") -> ซ้ำกัน | I20: Compressed Natural Gas | O20: IPCC defaults (2006), volume 2, chapter 2, table 2.3, p.2.18 - 2.19 และ Convert ค่าโดยอาศัยค่าคุณลักษณะเชื้อเพลิง | Q20: 0 | R20: 2.093e-05 | S20: 2.093e-06 | AC20: พฤษภาคม 2569 | AF20: 1 | AH20: {}
A21: 289cf586-3ecb-5ebf-86c7-a3137d4ead97 | B21: a1000001-0001-4001-8001-000000000001 | C21: Biogasollne (Ethanol) | E21: Liter | F21: 1.5019201 | G21: ='Fuel Resources ล่าสุด'!G21 -> Diesel B7: Report in Scope 1 | H21: =IF(COUNTIF(G:G,C21)>0,"ซ้ำกัน","ไม่ซ้ำกัน") -> ไม่ซ้ำกัน | I21: Crude tanker | O21: IPCC defaults (2006), volume 2, chapter 2, table 2.3, p.2.18 - 2.19 และ Convert ค่าโดยอาศัยค่าคุณลักษณะเชื้อเพลิง | P21: 1.4967828 | R21: 6.3423e-05 | S21: 1.26846e-05 | AC21: พฤษภาคม 2569 | AF21: 1 | AH21: {}
A22: 570b41ed-5259-54de-bc53-a074e557a7c3 | B22: a1000003-0003-4003-8003-000000000007 | C22: Bisphenol A (BPA) | D22: กลุ่มปิโตรเคมี | E22: kg | F22: 3.5411 | G22: ='Fuel Resources ล่าสุด'!G22 -> Diesel B7: Report in Biogenic CO2 emissions | H22: =IF(COUNTIF(G:G,C22)>0,"ซ้ำกัน","ไม่ซ้ำกัน") -> ซ้ำกัน | I22: Crude tanker | O22: TGO_CFP_Thai National LCI Database, TIIS-MTEC-NSTDA (with TGO electricity 2022-2024) | AC22: พฤษภาคม 2569 | AF22: 1 | AH22: {}
A23: 7fbfa91f-0d4b-5b39-b203-5d47927dfa37 | B23: a1000001-0001-4001-8001-000000000001 | C23: Bituminous Coal: kg | E23: kg | F23: 2.5124677 | G23: ='Fuel Resources ล่าสุด'!G23 -> Diesel B20 (แบบคิด EF ของ Biofuel ด้วย) | H23: =IF(COUNTIF(G:G,C23)>0,"ซ้ำกัน","ไม่ซ้ำกัน") -> ไม่ซ้ำกัน | I23: Diesel (20) | O23: IPCC defaults (2006), volume 2, chapter 2, table 2.3, p.2.18 - 2.19 และ Convert ค่าโดยอาศัยค่าคุณลักษณะเชื้อเพลิง | P23: 2.494602 | Q23: 0 | R23: 0.0002637 | S23: 3.9555e-05 | AC23: พฤษภาคม 2569 | AF23: 1 | AH23: {}
A24: 60d4df0c-3c76-508f-9b96-b6bb993b2980 | B24: a1000001-0001-4001-8001-000000000001 | C24: Butane: kg | E24: kg | F24: 3.0344828 | G24: ='Fuel Resources ล่าสุด'!G24 -> Diesel B20: Report in Scope 1 | H24: =IF(COUNTIF(G:G,C24)>0,"ซ้ำกัน","ไม่ซ้ำกัน") -> ไม่ซ้ำกัน | I24: Diesel (20) | O24: 2C4H10+ 1302 → 8CO2+10H2O (MWC4H10 =58, MWCO2 =44) | P24: 3.0344828 | Q24: 0 | R24: 0 | S24: 0 | AC24: พฤษภาคม 2569 | AF24: 1 | AH24: {}
A25: fe860d23-43d7-5a40-a12b-d614f5782349 | B25: a1000003-0003-4003-8003-000000000007 | C25: Caprolactam (CPL) | D25: กลุ่มปิโตรเคมี | E25: kg | F25: 1.2916 | G25: ='Fuel Resources ล่าสุด'!G25 -> Diesel B20: Report in Biogenic CO2 emissions | H25: =IF(COUNTIF(G:G,C25)>0,"ซ้ำกัน","ไม่ซ้ำกัน") -> ซ้ำกัน | I25: Diesel (B7) | O25: Thai National LCI Database, TIIS-MTEC-NSTDA (with TGO electricity 2016-2018) | AC25: พฤษภาคม 2569 | AF25: 1 | AH25: {}
A26: 1aeb2a64-e876-5d18-91fd-cbadbdb6462c | B26: a1000003-0003-4003-8003-000000000007 | C26: Caprolactam (CPL) | D26: กลุ่มปิโตรเคมี | E26: kg | F26: 2.784 | G26: ='Fuel Resources ล่าสุด'!G26 -> Gasohol (E10) | H26: =IF(COUNTIF(G:G,C26)>0,"ซ้ำกัน","ไม่ซ้ำกัน") -> ซ้ำกัน | I26: Diesel (B7) | O26: TGO_CFP_Thai National LCI Database, TIIS-MTEC-NSTDA (with TGO electricity 2022-2024) | AC26: พฤษภาคม 2569 | AF26: 1 | AH26: {}
A27: b31f7d9c-d543-5fe3-8784-c9a4f1d77ba4 | B27: a1000003-0003-4003-8003-000000000007 | C27: Carbon dioxide (ก๊าซคาร์บอนไดออกไซด์) | D27: กลุ่มผลิตภัณฑ์จากก๊าซธรรมชาติ | E27: kg | F27: 1.0017 | G27: ='Fuel Resources ล่าสุด'!G27 -> Gasohol E10: Report in Scope 1 | H27: =IF(COUNTIF(G:G,C27)>0,"ซ้ำกัน","ไม่ซ้ำกัน") -> ไม่ซ้ำกัน | I27: Diesel (น้ำมันดีเซล / น้ำมันโซล่าร์) | O27: TGO_CFP_Thai National LCI Database, TIIS-MTEC-NSTDA (with TGO electricity 2022-2024) | AC27: พฤษภาคม 2569 | AF27: 1 | AH27: {}
A28: 3bc1f7d2-eb8d-5f61-8dce-3228f9848c01 | B28: a1000003-0003-4003-8003-000000000009 | C28: Carbon dioxide (ก๊าซคาร์บอนไดออกไซด์) | E28: kg | F28: 1.0506 | G28: ='Fuel Resources ล่าสุด'!G28 -> Gasohol E10: Report in Biogenic CO2 emissions | H28: =IF(COUNTIF(G:G,C28)>0,"ซ้ำกัน","ไม่ซ้ำกัน") -> ไม่ซ้ำกัน | I28: Diesel (น้ำมันดีเซล / น้ำมันโซล่าร์) | O28: Thai National LCI Database, TIIS-MTEC-NSTDA (with TGO electricity 2016-2018) | AC28: พฤษภาคม 2569 | AF28: 1 | AH28: {}
A29: 0af7d0dc-59a4-5d2c-bfd3-339adc176192 | B29: a1000003-0003-4003-8003-000000000009 | C29: Carbon dioxide (ก๊าซคาร์บอนไดออกไซด์) | E29: kg | F29: 1.0017 | G29: ='Fuel Resources ล่าสุด'!G29 -> Gasohol (E20) | H29: =IF(COUNTIF(G:G,C29)>0,"ซ้ำกัน","ไม่ซ้ำกัน") -> ไม่ซ้ำกัน | I29: Diesel (น้ำมันดีเซล / น้ำมันโซล่าร์) | O29: TGO_CFP_Thai National LCI Database, TIIS-MTEC-NSTDA (with TGO electricity 2022-2024) | AC29: พฤษภาคม 2569 | AF29: 1 | AH29: {}
A30: 2a7bf84f-7cb7-5156-9f73-5dd282057e60 | B30: a1000001-0001-4001-8001-000000000005 | C30: CH4 Septictank | E30: kgCH4 | F30: 28 | G30: ='Fuel Resources ล่าสุด'!G30 -> Gasohol E20: Report in Scope 1 | H30: =IF(COUNTIF(G:G,C30)>0,"ซ้ำกัน","ไม่ซ้ำกัน") -> ซ้ำกัน | I30: Diesel B20 | J30: จำนวนคน | L30: คน/เดือน | M30: จำนวนวันทำงาน | N30: วัน/เดือน | O30: IPCC, AR5 | R30: 1 | AC30: พฤษภาคม 2569 | AF30: 0.012 | AH30: {}
A31: 712761d7-bf17-5ad6-b46e-21bf704a9d94 | B31: a1000004-0004-4004-8004-000000000014 | C31: Charcoal | E31: kg | F31: 3.23456 | G31: ='Fuel Resources ล่าสุด'!G31 -> Gasohol E20: Report in Biogenic CO2 emissions | H31: =IF(COUNTIF(G:G,C31)>0,"ซ้ำกัน","ไม่ซ้ำกัน") -> ซ้ำกัน | I31: Diesel B20 | O31: IPCC defaults (2006), volume 2, chapter 2, table 2.3, p.2.18 - 2.19 และ Convert ค่าโดยอาศัยค่าคุณลักษณะเชื้อเพลิง | AC31: พฤษภาคม 2569 | AF31: 1 | AH31: {}
A32: 40c56372-19d9-5700-9500-d72ee11f7c19 | B32: a1000001-0001-4001-8001-000000000001 | C32: Charcoal | E32: kg | F32: 0.054872 | G32: ='Fuel Resources ล่าสุด'!G32 -> Gasohol (E85) | H32: =IF(COUNTIF(G:G,C32)>0,"ซ้ำกัน","ไม่ซ้ำกัน") -> ซ้ำกัน | I32: Diesel: Aggriculture, L | O32: IPCC defaults (2006), volume 2, chapter 2, table 2.3, p.2.18 - 2.19 และ Convert ค่าโดยอาศัยค่าคุณลักษณะเชื้อเพลิง | Q32: 0 | R32: 0.0008664 | S32: 0.00011552 | AC32: พฤษภาคม 2569 | AF32: 1 | AH32: {}
A33: 2f367e19-019f-54fa-96af-14de1b6834b6 | B33: a1000003-0003-4003-8003-00000000000a | C33: Chemical tanker | D33: Marine transport | E33: tkm | F33: 0.01031 | G33: ='Fuel Resources ล่าสุด'!G33 -> Gasohol E85: Report in Scope 1 | H33: =IF(COUNTIF(G:G,C33)>0,"ซ้ำกัน","ไม่ซ้ำกัน") -> ไม่ซ้ำกัน | I33: Diesel: Forestry, L | O33: DEFRA: Greenhouse gas reporting: conversion factors 2025 | AC33: พฤษภาคม 2569 | AF33: 1 | AH33: {}
A34: d61a7c7c-cd2b-5bd9-9f07-b8d83ebee2d8 | B34: a1000003-0003-4003-8003-00000000000f | C34: Chemical tanker | D34: Marine transport | E34: tkm | F34: 0.01031 | G34: ='Fuel Resources ล่าสุด'!G34 -> Gasohol E85: Report in Biogenic CO2 emissions | H34: =IF(COUNTIF(G:G,C34)>0,"ซ้ำกัน","ไม่ซ้ำกัน") -> ไม่ซ้ำกัน | I34: Diesel: Household, L | O34: DEFRA: Greenhouse gas reporting: conversion factors 2025 | AC34: พฤษภาคม 2569 | AF34: 1 | AH34: {}
A35: 6434daae-847c-5f33-b285-b01a2d33dbb6 | B35: a1000001-0001-4001-8001-000000000003 | C35: CNG: kg | E35: kg | F35: 2.2539509 | G35: ='Fuel Resources ล่าสุด'!G35 -> Lignite | H35: =IF(COUNTIF(G:G,C35)>0,"ซ้ำกัน","ไม่ซ้ำกัน") -> ไม่ซ้ำกัน | I35: Diesel: Industry, L | O35: IPCC defaults (2006), volume 2, chapter 3, table 3.2.1 & 3.2.2 และ Convert ค่าโดยอาศัยค่าคุณลักษณะเชื้อเพลิง | P35: 2.12619 | Q35: 0 | R35: 0.0034868 | S35: 0.0001137 | AC35: พฤษภาคม 2569 | AF35: 1 | AH35: {}
A36: 42ef7d0d-10ce-5d13-86ef-a84251384613 | B36: a1000004-0004-4004-8004-000000000014 | C36: Cob | E36: kg | F36: 1.678 | G36: ='Fuel Resources ล่าสุด'!G36 -> Anthracite | H36: =IF(COUNTIF(G:G,C36)>0,"ซ้ำกัน","ไม่ซ้ำกัน") -> ซ้ำกัน | I36: Diesel: L | O36: IPCC defaults (2006), volume 2, chapter 2, table 2.3, p.2.18 - 2.19 และ Convert ค่าโดยอาศัยค่าคุณลักษณะเชื้อเพลิง | AC36: พฤษภาคม 2569 | AF36: 1 | AH36: {}
A37: f3abb2e2-9639-5445-ae13-476965f5cdf4 | B37: a1000001-0001-4001-8001-000000000001 | C37: Cob | E37: kg | F37: 0.031882 | G37: ='Fuel Resources ล่าสุด'!G37 -> Bituminous Coal | H37: =IF(COUNTIF(G:G,C37)>0,"ซ้ำกัน","ไม่ซ้ำกัน") -> ซ้ำกัน | I37: Diesel: L | O37: IPCC defaults (2006), volume 2, chapter 2, table 2.3, p.2.18 - 2.19 และ Convert ค่าโดยอาศัยค่าคุณลักษณะเชื้อเพลิง | Q37: 0 | R37: 0.0005034 | S37: 6.712e-05 | AC37: พฤษภาคม 2569 | AF37: 1 | AH37: {}
A38: 0d086e51-c6b5-5623-8dea-d016d82377b3 | B38: a1000001-0001-4001-8001-000000000001 | C38: Coking Coal: kg | E38: kg | F38: 2.6325173 | G38: ='Fuel Resources ล่าสุด'!G38 -> Coking Coal | H38: =IF(COUNTIF(G:G,C38)>0,"ซ้ำกัน","ไม่ซ้ำกัน") -> ไม่ซ้ำกัน | I38: Domestic | O38: IPCC defaults (2006), volume 2, chapter 2, table 2.3, p.2.18 - 2.19 และ Convert ค่าโดยอาศัยค่าคุณลักษณะเชื้อเพลิง | P38: 2.613798 | Q38: 0 | R38: 0.0002763 | S38: 4.1445e-05 | AC38: พฤษภาคม 2569 | AF38: 1 | AH38: {}
A39: dbbacb54-2cdc-5dc9-9697-eb4051a59fd4 | B39: a1000003-0003-4003-8003-00000000000c | C39: Compressed Natural Gas | D39: Road ทราบปริมาณเชื้อเพลิง | E39: kg | F39: 2.2609245 | G39: ='Fuel Resources ล่าสุด'!G39 -> Fuel wood | H39: =IF(COUNTIF(G:G,C39)>0,"ซ้ำกัน","ไม่ซ้ำกัน") -> ไม่ซ้ำกัน | I39: Domestic | O39: IPCC Vol.2 table 3.2.1, 3.2.2, PTT | AC39: พฤษภาคม 2569 | AF39: 1 | AH39: {}
A40: 04656bc9-673e-5f20-b6d1-0854b7f4ced0 | B40: a1000003-0003-4003-8003-00000000000c | C40: Compressed Natural Gas | D40: Road ทราบปริมาณเชื้อเพลิง | E40: kg | F40: 2.2539509 | G40: ='Fuel Resources ล่าสุด'!G40 -> Fuel wood: Report in Scope 1 | H40: =IF(COUNTIF(G:G,C40)>0,"ซ้ำกัน","ไม่ซ้ำกัน") -> ไม่ซ้ำกัน | I40: Electricity, grid mix (ไฟฟ้า) | O40: IPCC defaults (2006), volume 2, chapter 3, table 3.2.1 & 3.2.2 และ Convert ค่าโดยอาศัยค่าคุณลักษณะเชื้อเพลิง | AC40: พฤษภาคม 2569 | AF40: 1 | AH40: {}
...
